<?xml version="1.0"?>
<robot xmlns:xacro="http://www.ros.org/wiki/xacro">

  <!-- ============================================== -->
  <xacro:property name="WHEEL_RADIUS" value="0.04" />
  <xacro:property name="WHEEL_LENGTH" value="0.025" />
  <xacro:property name="WHEEL_VISUAL_ENABLE" value="true" />
  
  <!-- ============================================== -->
  <xacro:macro name="mecanum_wheel" params="name x y">
    <link name="${name}_link">
      
      <xacro:if value="${WHEEL_VISUAL_ENABLE}">
        <visual>
          <geometry><cylinder radius="${WHEEL_RADIUS}" length="${WHEEL_LENGTH}"/></geometry>
          <material name="black"><color rgba="0 0 0 1"/></material>
          <origin rpy="1.5707 0 0"/> 
        </visual>
      </xacro:if>
      
      <collision>
        <geometry><cylinder radius="${WHEEL_RADIUS}" length="${WHEEL_LENGTH}"/></geometry>
        <origin rpy="1.5707 0 0"/>
      </collision>
      
      <inertial>
        <mass value="10.0"/>
        <inertia ixx="0.0007" ixy="0" ixz="0" iyy="0.0007" iyz="0" izz="0.0012"/>
      </inertial>
    </link>
    
    <joint name="${name}_joint" type="continuous">
      <parent link="base_link"/>
      <child link="${name}_link"/>

      <origin xyz="${x} ${y} 0.01"/> 
      <axis xyz="0 1 0"/>
      <dynamics damping="1.0" friction="0.5"/> 
    </joint>

    <gazebo reference="${name}_link">
      <mu1>10.0</mu1> 
      <mu2>10.0</mu2>
      <kp>1000000000.0.0</kp>
      <kd>100000.0</kd>      
      <minDepth>0.0001</minDepth>
    </gazebo>
  </xacro:macro>

  <!-- ============================================== -->
  <xacro:mecanum_wheel name="front_left"  x="0.08"  y="0.09"/>
  <xacro:mecanum_wheel name="front_right" x="0.08"  y="-0.09"/>
  <xacro:mecanum_wheel name="rear_left"   x="-0.08" y="0.09"/>
  <xacro:mecanum_wheel name="rear_right"  x="-0.08" y="-0.09"/>

</robot>
