<?xml version="1.0" encoding="utf-8"?>
<robot name="gripper" xmlns:xacro="http://ros.org/wiki/xacro">
  <xacro:property name="M_PI"   value="3.1415926535897931"/>

  <link
    name="r_link">
    <inertial>
      <origin
        xyz="0.00149476093597167 0.000447162363651166 0.0059221337188245"
        rpy="0 0 0" />
      <mass
        value="0.00206265647704866" />
      <inertia
        ixx="3.97215843669342E-07"
        ixy="-2.75699120579387E-10"
        ixz="-2.19901048536124E-09"
        iyy="3.22472627342115E-07"
        iyz="1.07303783544668E-08"
        izz="7.78708186672131E-08" />
    </inertial>
    <visual>
      <origin
        xyz="0 0 0"
        rpy="0 0 0" />
      <geometry>
        <mesh
          filename="file://$(find jetspider_description)/meshes/gripper/r_link.STL" />
      </geometry>
      <material name="black"/>
    </visual>
    <collision>
      <origin
        xyz="0 0 0"
        rpy="0 0 0" />
      <geometry>
        <mesh
          filename="file://$(find jetspider_description)/meshes/gripper/r_link.STL" />
      </geometry>
    </collision>
  </link>
  <joint
    name="r_joint"
    type="revolute">
    <origin
      xyz="-0.0066673 -0.013997 0.033624"
      rpy="0.69807 -0.013488 0.00018494" />
    <parent
      link="gripper_link" />
    <child
      link="r_link" />
    <axis
      xyz="0.99996 -0.004699 -0.0070434" />
    <limit
      lower="-0.66"
      upper="0.75"
      effort="1000"
      velocity="10" />
  </joint>
  <link
    name="l_link">
    <inertial>
      <origin
        xyz="0.0014957 -0.00057138 0.0064437"
        rpy="0 0 0" />
      <mass
        value="0.00218924933187322" />
      <inertia
        ixx="4.0534152698165E-07"
        ixy="3.60077827494503E-10"
        ixz="-1.99675888093364E-09"
        iyy="3.31222174181852E-07"
        iyz="-8.79337758250917E-09"
        izz="7.74319582642917E-08" />
    </inertial>
    <visual>
      <origin
        xyz="0 0 0"
        rpy="0 0 0" />
      <geometry>
        <mesh
          filename="file://$(find jetspider_description)/meshes/gripper/l_link.STL" />
      </geometry>
      <material name="black"/>
    </visual>
    <collision>
      <origin
        xyz="0 0 0"
        rpy="0 0 0" />
      <geometry>
        <mesh
          filename="file://$(find jetspider_description)/meshes/gripper/l_link.STL" />
      </geometry>
    </collision>
  </link>
  <joint
    name="l_joint"
    type="revolute">
    <origin
      xyz="-0.0066671 0.014011 0.033624"
      rpy="-0.69813 -0.013488 0.00018494" />
    <parent
      link="gripper_link" />
    <child
      link="l_link" />
    <axis
      xyz="0.99997 0.0055811 -0.0058397" />
    <limit
      lower="-0.66"
      upper="0.75"
      effort="1000"
      velocity="10" />
    <mimic
      joint="r_joint"
      multiplier="-1"
      offset="0" />
  </joint>
  <link
    name="l_in_link">
    <inertial>
      <origin
        xyz="0.0017483 -7.3491E-05 0.013616"
        rpy="0 0 0" />
      <mass
        value="0.000776872870694597" />
      <inertia
        ixx="9.87455572181138E-08"
        ixy="5.06340928475727E-12"
        ixz="-6.79685646256186E-10"
        iyy="9.76635148452203E-08"
        iyz="-6.12115908323794E-12"
        izz="2.25695364751658E-09" />
    </inertial>
    <visual>
      <origin
        xyz="0 0 0"
        rpy="0 0 0" />
      <geometry>
        <mesh
          filename="file://$(find jetspider_description)/meshes/gripper/l_in_link.STL" />
      </geometry>
      <material name="black"/>
    </visual>
    <collision>
      <origin
        xyz="0 0 0"
        rpy="0 0 0" />
      <geometry>
        <mesh
          filename="file://$(find jetspider_description)/meshes/gripper/l_in_link.STL" />
      </geometry>
    </collision>
  </link>
  <joint
    name="l_in_joint"
    type="revolute">
    <origin
      xyz="-0.0069227 0.0050038 0.052592"
      rpy="-0.70347 -0.013488 0.00018494" />
    <parent
      link="gripper_link" />
    <child
      link="l_in_link" />
    <axis
      xyz="0.99996 0.0046983 -0.0070439" />
    <limit
      lower="-0.66"
      upper="0.75"
      effort="1000"
      velocity="10" />
    <mimic
      joint="r_joint"
      multiplier="-1"
      offset="0" />
  </joint>
  <link
    name="l_out_link">
    <inertial>
      <origin
        xyz="0.0030024 0.0023219 0.0029375"
        rpy="0 0 0" />
      <mass
        value="0.00384735908281124" />
      <inertia
        ixx="2.8323E-07"
        ixy="-6.2446E-12"
        ixz="1.1309E-11"
        iyy="2.5422E-07"
        iyz="6.0402E-08"
        izz="5.0204E-08" />
    </inertial>
    <visual>
      <origin
        xyz="0 0 0"
        rpy="0 0 0" />
      <geometry>
        <mesh
          filename="file://$(find jetspider_description)/meshes/gripper/l_out_link.STL" />
      </geometry>
      <material name="black"/>
    </visual>
    <collision>
      <origin
        xyz="0 0 0"
        rpy="0 0 0" />
      <geometry>
        <mesh
          filename="file://$(find jetspider_description)/meshes/gripper/l_out_link.STL" />
      </geometry>
    </collision>
  </link>
  <joint
    name="l_out_joint"
    type="revolute">
    <origin
      xyz="0.0030045 -0.00016649 0.030005"
      rpy="0.70347 -0.00059773 -0.00074951" />
    <parent
      link="l_in_link" />
    <child
      link="l_out_link" />
    <axis
      xyz="-1 0.00021123 0" />
    <limit
      lower="-0.66"
      upper="0.75"
      effort="1000"
      velocity="10" />
    <mimic
      joint="r_joint"
      multiplier="-1"
      offset="0" />
  </joint>
  <link
    name="r_in_link">
    <inertial>
      <origin
        xyz="0.0017449715909225 4.83723236602285E-05 0.0136380601242236"
        rpy="0 0 0" />
      <mass
        value="0.000776872870694522" />
      <inertia
        ixx="9.87465668171204E-08"
        ixy="-5.11173808106636E-12"
        ixz="-6.79692406191707E-10"
        iyy="9.7664293636849E-08"
        iyz="-5.14018800149497E-13"
        izz="2.25718458778487E-09" />
    </inertial>
    <visual>
      <origin
        xyz="0 0 0"
        rpy="0 0 0" />
      <geometry>
        <mesh
          filename="file://$(find jetspider_description)/meshes/gripper/r_in_link.STL" />
      </geometry>
      <material name="black"/>
    </visual>
    <collision>
      <origin
        xyz="0 0 0"
        rpy="0 0 0" />
      <geometry>
        <mesh
          filename="file://$(find jetspider_description)/meshes/gripper/r_in_link.STL" />
      </geometry>
    </collision>
  </link>
  <joint
    name="r_in_joint"
    type="revolute">
    <origin
      xyz="-0.0069226 -0.0049819 0.052575"
      rpy="0.70163 -0.013488 0.00018494" />
    <parent
      link="gripper_link" />
    <child
      link="r_in_link" />
    <axis
      xyz="-0.99996 0.0046987 0.0070436" />
    <limit
      lower="-0.66"
      upper="0.75"
      effort="1000"
      velocity="10" />
    <mimic
      joint="r_joint"
      multiplier="-1"
      offset="0" />
  </joint>
  <link
    name="r_out_link">
    <inertial>
      <origin
        xyz="0.0028811 -0.0023201 -0.0030022"
        rpy="0 0 0" />
      <mass
        value="0.0038474" />
      <inertia
        ixx="5.0201E-08"
        ixy="-6.0409E-08"
        ixz="-1.1659E-11"
        iyy="2.5422E-07"
        iyz="-4.9052E-12"
        izz="2.8323E-07" />
    </inertial>
    <visual>
      <origin
        xyz="0 0 0"
        rpy="0 0 0" />
      <geometry>
        <mesh
          filename="file://$(find jetspider_description)/meshes/gripper/r_out_link.STL" />
      </geometry>
      <material name="black"/>
    </visual>
    <collision>
      <origin
        xyz="0 0 0"
        rpy="0 0 0" />
      <geometry>
        <mesh
          filename="file://$(find jetspider_description)/meshes/gripper/r_out_link.STL" />
      </geometry>
    </collision>
  </link>
  <joint
    name="r_out_joint"
    type="revolute">
    <origin
      xyz="0.0029971 0.00014485 0.030071"
      rpy="-1.5721 -0.86916 1.5723" />
    <parent
      link="r_in_link" />
    <child
      link="r_out_link" />
    <axis
      xyz="0.0091248 -0.00051139 0.99996" />
    <limit
      lower="-0.66"
      upper="0.75"
      effort="1000"
      velocity="10" />
    <mimic
      joint="r_joint"
      multiplier="1"
      offset="0" />
  </joint>
</robot>